<?xml version="1.0"?>
<robot name="darnet" xmlns:xacro="http://www.ros.org/wiki/xacro">

  <xacro:include filename="$(find darnet_description)/urdf/macros.xacro" />
  <xacro:include filename="$(find darnet_description)/urdf/materials.xacro" />
  

    <!-- ********************************* Badan ****************************** -->
  <link name="BadanBawahRevisi">
    <visual>
      <origin xyz="0 0 0" rpy="0 0 0" />
      <geometry>
        <mesh filename="package://darnet_description/meshes/darnet_stl/badan/BadanBawahRevisi.stl" scale="0.001 0.001 0.001" />
      </geometry>
      <material name="black" /> <!-- unfortunately you cant give color to stl files in gazebo -->
    </visual>
    <collision>
      <origin xyz="0 0 0" rpy="0 0 0" /> <!-- in radians -->
      <geometry>
        <mesh filename="package://darnet_description/meshes/darnet_stl/badan/BadanBawahRevisi.stl" scale="0.001 0.001 0.001" />
      </geometry>
    </collision>
    <inertial>
      <origin xyz="-0.068 0.024 -0.066" rpy="0 0 0" />
      <mass value="0.383" /> <!-- in kg -->
      <!--  -->
      <inertia
                ixx="0.003" 
                ixy="0.001" 
                ixz="-0.002"
                iyy="0.005" 
                iyz="0.001"
                izz="0.004" />
    </inertial>
  </link>
  
  <joint name="BadanBawahRevisi_to_BadanDepanRevisi_3DPrint" type="fixed">
        <parent link="BadanBawahRevisi"/>
        <child link="BadanDepanRevisi_3DPrint"/>
        <origin rpy="0 3.14 0" xyz="-0.136273 -0.004696 -0.13"/>
    </joint>
    
    
   <link name="BadanDepanRevisi_3DPrint">
    <visual>
      <origin xyz="0 0 0" rpy="0 0 0" />
      <geometry>
        <mesh filename="package://darnet_description/meshes/darnet_stl/badan/BadanDepanRevisi_3DPrint.stl" scale="0.001 0.001 0.001" />
      </geometry>
      <material name="black" /> <!-- unfortunately you cant give color to stl files in gazebo -->
    </visual>
    <collision>
      <origin xyz="0 0 0" rpy="0 0 0" /> <!-- in radians -->
      <geometry>
        <mesh filename="package://darnet_description/meshes/darnet_stl/badan/BadanDepanRevisi_3DPrint.stl" scale="0.001 0.001 0.001" />
      </geometry>
    </collision>
    <inertial>
      <origin xyz="-0.069 0.042 0.001" rpy="0 0 0" />
      <mass value="0.1" /> <!-- in kg -->
      <!--  -->
      <inertia
                ixx="1.0609e-3" 
                ixy="1e-3" 
                ixz="1e-3"
                iyy="5.0409e-3" 
                iyz="1e-3"
                izz="5.865e-3" />
    </inertial>
  </link>
  
  
  
  <joint name="BadanBawahRevisi_to_BadanAtasRevisi" type="fixed">
        <parent link="BadanBawahRevisi"/>
        <child link="BadanAtasRevisi"/>
        <origin rpy="0 0 0" xyz="0 0.076546 0"/>
    </joint>
  
  <link name="BadanAtasRevisi">
    <visual>
      <origin xyz="0 0 0" rpy="0 0 0" />
      <geometry>
        <mesh filename="package://darnet_description/meshes/darnet_stl/badan/BadanAtasRevisi.stl" scale="0.001 0.001 0.001" />
      </geometry>
      <material name="black" /> <!-- unfortunately you cant give color to stl files in gazebo -->
    </visual>
    <collision>
      <origin xyz="0 0 0" rpy="0 0 0" /> <!-- in radians -->
      <geometry>
        <mesh filename="package://darnet_description/meshes/darnet_stl/badan/BadanAtasRevisi.stl" scale="0.001 0.001 0.001" />
      </geometry>
    </collision>
    <inertial>
      <origin xyz="-0.068 0.006 -0.059" rpy="0 0 0" />
      <mass value="0.1" /> <!-- in kg -->
      <!--  -->
      <inertia
                ixx="0.001" 
                ixy="0.0001" 
                ixz="-0.001"
                iyy="0.003" 
                iyz="0.0001"
                izz="0.002" />
    </inertial>
  </link>
  
  
  
  <joint name="BadanBawahRevisi_to_TempatBatteryRevisi2" type="fixed">
        <parent link="BadanBawahRevisi"/>
        <child link="TempatBatteryRevisi2"/>
        <origin rpy="0 0 0" xyz="-0.0348 -0.041 0"/>
    </joint>
  
  <link name="TempatBatteryRevisi2">
    <visual>
      <origin xyz="0 0 0" rpy="0 0 0" />
      <geometry>
        <mesh filename="package://darnet_description/meshes/darnet_stl/badan/TempatBatteryRevisi2.stl" scale="0.001 0.001 0.001" />
      </geometry>
      <material name="black" /> <!-- unfortunately you cant give color to stl files in gazebo -->
    </visual>
    <collision>
      <origin xyz="0 0 0" rpy="0 0 0" /> <!-- in radians -->
      <geometry>
        <mesh filename="package://darnet_description/meshes/darnet_stl/badan/TempatBatteryRevisi2.stl" scale="0.001 0.001 0.001" />
      </geometry>
    </collision>
    <inertial>
      <origin xyz="-0.033 0.006 -0.084" rpy="0 0 0" />
      <mass value="0.136" /> <!-- in kg -->
      <!--  -->
      <inertia
                ixx="0.001" 
                ixy="0.0001" 
                ixz="-0.0001"
                iyy="0.001" 
                iyz="0.0001"
                izz="0.0001" />
    </inertial>
  </link>
  
  
  
  
  <joint name="BadanBawahRevisi_to_PantatKiri" type="fixed">
        <parent link="BadanBawahRevisi"/>
        <child link="PantatKiri"/>
        <origin rpy="0 0 0" xyz="-0.00353 -0.041 -0.0105"/>
    </joint>
  
  <link name="PantatKiri">
    <visual>
      <origin xyz="0 0 0" rpy="0 0 0" />
      <geometry>
        <mesh filename="package://darnet_description/meshes/darnet_stl/badan/PantatKiri.stl" scale="0.001 0.001 0.001" />
      </geometry>
      <material name="black" /> <!-- unfortunately you cant give color to stl files in gazebo -->
    </visual>
    <collision>
      <origin xyz="0 0 0" rpy="0 0 0" /> <!-- in radians -->
      <geometry>
        <mesh filename="package://darnet_description/meshes/darnet_stl/badan/PantatKiri.stl" scale="0.001 0.001 0.001" />
      </geometry>
    </collision>
    <inertial>
      <origin xyz="-0.013 0.021 -0.016" rpy="0 0 0" />
      <mass value="0.064" /> <!-- in kg -->
      <!--  -->
      <inertia
                ixx="1.0609e-3" 
                ixy="1e-3" 
                ixz="-1e-3"
                iyy="5.0409e-3" 
                iyz="1e-3"
                izz="5.865e-3" />
    </inertial>
  </link>
  
  
  
  
  <joint name="BadanBawahRevisi_to_PantatKanan" type="fixed">
        <parent link="BadanBawahRevisi"/>
        <child link="PantatKanan"/>
        <origin rpy="0 0 0" xyz="-0.10047 -0.042 -0.0275"/>
    </joint>
  
  <link name="PantatKanan">
    <visual>
      <origin xyz="0 0 0" rpy="0 0 0" />
      <geometry>
        <mesh filename="package://darnet_description/meshes/darnet_stl/badan/PantatKanan.stl" scale="0.001 0.001 0.001" />
      </geometry>
      <material name="black" /> <!-- unfortunately you cant give color to stl files in gazebo -->
    </visual>
    <collision>
      <origin xyz="0 0 0" rpy="0 0 0" /> <!-- in radians -->
      <geometry>
        <mesh filename="package://darnet_description/meshes/darnet_stl/badan/PantatKanan.stl" scale="0.001 0.001 0.001" />
      </geometry>
    </collision>
    <inertial>
      <origin xyz="-0.018 0.022 0.002" rpy="0 0 0" />
      <mass value="0.071" /> <!-- in kg -->
      <!--  -->
      <inertia
                ixx="1.0609e-3" 
                ixy="1e-3" 
                ixz="1e-3"
                iyy="5.0409e-3" 
                iyz="-1e-3"
                izz="5.865e-3" />
    </inertial>
  </link>
  
  <!-- *************************************************************** -->
  
  <!-- ********************************* kepala ****************************** -->
    
    <joint name="BadanBawahRevisi_to_6_PR13_B_SPACER_PELV" type="fixed">
        <parent link="BadanBawahRevisi"/>
        <child link="6_PR13_B_SPACER_PELV"/>
        <origin rpy="3.14 0 0" xyz="-0.1045 0.097648 -0.0825"/>
    </joint>
    
    <link name="6_PR13_B_SPACER_PELV">
    <visual>
      <origin xyz="0 0 0" rpy="0 0 0" />
      <geometry>
        <mesh filename="package://darnet_description/meshes/darnet_stl/kepala/6_PR13_B_SPACER_PELV.stl" scale="0.001 0.001 0.001" />
      </geometry>
      <material name="grey" /> <!-- unfortunately you cant give color to stl files in gazebo -->
    </visual>
    <collision>
      <origin xyz="0 0 0" rpy="0 0 0" /> <!-- in radians -->
      <geometry>
        <mesh filename="package://darnet_description/meshes/darnet_stl/kepala/6_PR13_B_SPACER_PELV.stl" scale="0.001 0.001 0.001" />
      </geometry>
    </collision>
    <inertial>
      <origin xyz="0.037 0.018 -0.005" rpy="0 0 0" />
      <mass value="0.015" /> <!-- in kg -->
      <!--  -->
      <inertia
                ixx="1.0609e-3" 
                ixy="-1e-3" 
                ixz="1e-3"
                iyy="5.0409e-3" 
                iyz="1e-3"
                izz="5.865e-3" />
    </inertial>
  </link>
  
  
  
  
  <joint name="6_PR13_B_SPACER_PELV_to_MX-28AT_AR_19" type="fixed">
        <parent link="6_PR13_B_SPACER_PELV"/>
        <child link="MX-28AT_AR_19"/>
        <origin rpy="1.57 0 0" xyz="0.037 0 0"/>
    </joint>
  
  <link name="MX-28AT_AR_19">
    <visual>
      <origin xyz="0 0 0" rpy="0 0 0" />
      <geometry>
        <mesh filename="package://darnet_description/meshes/darnet_stl/kepala/MX-28AT_AR.stl" scale="0.001 0.001 0.001" />
      </geometry>
      <material name="grey" /> <!-- unfortunately you cant give color to stl files in gazebo -->
    </visual>
    <collision>
      <origin xyz="0 0 0" rpy="0 0 0" /> <!-- in radians -->
      <geometry>
        <mesh filename="package://darnet_description/meshes/darnet_stl/kepala/MX-28AT_AR.stl" scale="0.001 0.001 0.001" />
      </geometry>
    </collision>
    <inertial>
      <origin xyz="0.0 -0.011 0.0" rpy="0 0 0" />
      <mass value="0.072" /> <!-- in kg -->
      <!--  -->
      <inertia
                ixx="1.0609e-3" 
                ixy="1e-3" 
                ixz="-1e-3"
                iyy="5.0409e-3" 
                iyz="-1e-3"
                izz="5.865e-3" />
    </inertial>
  </link>
  
    
    <joint name="MX-28AT_AR_19_to_2_FR07_H104" type="revolute">
        <parent link="MX-28AT_AR_19"/>
        <child link="2_FR07_H104"/>
        <origin rpy="0 0 0" xyz="0 0 0.0225"/> <!-- origin ini untuk lokasi joint kita -->
        <axis xyz="0 0 1"/>
        <limit effort="1.4" lower="-2.4" upper="2.4" velocity="6.96"/>
        <dynamics damping="0.0" friction="0.0"/>
    </joint>
  
  <link name="2_FR07_H104">
    <visual>
      <origin xyz="0 0.005 -0.092835" rpy="1.57 0 0" /> <!-- origin ini untuk ubah2 pose benda terhadap joint kita -->
      <geometry>
        <mesh filename="package://darnet_description/meshes/darnet_stl/kepala/2_FR07_H104.stl" scale="0.001 0.001 0.001" />
      </geometry>
      <material name="black" /> <!-- unfortunately you cant give color to stl files in gazebo -->
    </visual>
    <collision>
      <origin xyz="0 0.005 -0.092835" rpy="1.57 0 0" /> <!-- in radians -->
      <geometry>
        <mesh filename="package://darnet_description/meshes/darnet_stl/kepala/2_FR07_H104.stl" scale="0.001 0.001 0.001" />
      </geometry>
    </collision>
    <inertial>
      <origin xyz="0.0 0.004 0.1" rpy="0 0 0" />
      <mass value="0.037" /> <!-- in kg -->
      <!--  -->
      <inertia
                ixx="1.0609e-3" 
                ixy="1e-3" 
                ixz="1e-3"
                iyy="5.0409e-3" 
                iyz="-1e-3"
                izz="5.865e-3" />
    </inertial>
  </link>
  
  
  
  
  <joint name="2_FR07_H104_to_MX-28AT_AR_20" type="revolute">
        <parent link="2_FR07_H104"/>
        <child link="MX-28AT_AR_20"/>
        <origin rpy="0 1.57 0" xyz="0 0 0.028"/>
        <axis xyz="0 0 1"/>
        <limit effort="1.4" lower="-2.15" upper="1.15" velocity="6.96"/>
        <dynamics damping="0.0" friction="0.0"/>
    </joint>
  
  <link name="MX-28AT_AR_20">
    <visual>
      <origin xyz="0 0 0" rpy="0 0 -0.66549404" />
      <geometry>
        <mesh filename="package://darnet_description/meshes/darnet_stl/kepala/MX-28AT_AR.stl" scale="0.001 0.001 0.001" />
      </geometry>
      <material name="grey" /> <!-- unfortunately you cant give color to stl files in gazebo -->
    </visual>
    <collision>
      <origin xyz="0 0 0" rpy="0 0 -0.66549404" /> <!-- in radians -->
      <geometry>
        <mesh filename="package://darnet_description/meshes/darnet_stl/kepala/MX-28AT_AR.stl" scale="0.001 0.001 0.001" />
      </geometry>
    </collision>
    <inertial>
      <origin xyz="0.0 -0.011 0.0" rpy="0 0 0" />
      <mass value="0.072" /> <!-- in kg -->
      <!--  -->
      <inertia
                ixx="1.0609e-3" 
                ixy="1e-3" 
                ixz="-1e-3"
                iyy="5.0409e-3" 
                iyz="-1e-3"
                izz="5.865e-3" />
    </inertial>
  </link>
  
  
  
  
  <joint name="MX-28AT_AR_20_to_Kepala" type="fixed">
        <parent link="MX-28AT_AR_20"/>
        <child link="Kepala"/>
        <origin rpy="0 1.57 0" xyz="0.098921 -0.102268 0.0005"/>
    </joint>
    
    <link name="Kepala">
    <visual>
      <origin xyz="0 0.0025 0.0025" rpy="-2.23629037 0 3.14" />
      <geometry>
        <mesh filename="package://darnet_description/meshes/darnet_stl/kepala/Kepala.stl" scale="0.001 0.001 0.001" />
      </geometry>
      <material name="grey" /> <!-- unfortunately you cant give color to stl files in gazebo -->
    </visual>
    <collision>
      <origin xyz="0 0.0025 0.0025" rpy="-2.23629037 0 3.14" /> <!-- in radians -->
      <geometry>
        <mesh filename="package://darnet_description/meshes/darnet_stl/kepala/Kepala.stl" scale="0.001 0.001 0.001" />
      </geometry>
    </collision>
    <inertial>
      <origin xyz="0.0 -0.027 -0.156" rpy="0 0 0" />
      <mass value="0.038" /> <!-- in kg -->
      <!--  -->
      <inertia
                ixx="1.0609e-3" 
                ixy="1e-3" 
                ixz="1e-3"
                iyy="5.0409e-3" 
                iyz="-1e-3"
                izz="1.0609e-3" />
    </inertial>
  </link>
  
  
  
  <joint name="Kepala_to_camera_holder" type="fixed">
        <parent link="Kepala"/>
        <child link="camera_holder"/>
        <origin rpy="0 3.14 0" xyz="-0.015 0.065396 -0.142955"/>
    </joint>
    
    <link name="camera_holder">
    <visual>
      <origin xyz="0.0005 0.0033 -0.0028" rpy="1.57 0 0" />
      <geometry>
        <mesh filename="package://darnet_description/meshes/darnet_stl/kepala/camera_holder.stl" scale="0.001 0.001 0.001" />
      </geometry>
      <material name="black" /> <!-- unfortunately you cant give color to stl files in gazebo -->
    </visual>
    <collision>
      <origin xyz="0.0005 0.0033 -0.0028" rpy="1.57 0 0" /> <!-- in radians -->
      <geometry>
        <mesh filename="package://darnet_description/meshes/darnet_stl/kepala/camera_holder.stl" scale="0.001 0.001 0.001" />
      </geometry>
    </collision>
    <inertial>
      <origin xyz="-0.016 0.005 -0.015" rpy="0 0 0" />
      <mass value="0.016" /> <!-- in kg -->
      <!--  -->
      <inertia
                ixx="1.0609e-3" 
                ixy="1e-3" 
                ixz="-1e-3"
                iyy="5.0409e-3" 
                iyz="1e-3"
                izz="1.0609e-3" />
    </inertial>
  </link>
  
  
  
  
  <joint name="camera_holder_to_Intel_D415" type="fixed">
        <parent link="camera_holder"/>
        <child link="Intel_D415"/>
        <origin rpy="0 3.14 0" xyz="0.0225 0.020260 0.018063"/>
    </joint>
    
    <link name="Intel_D415">
    <visual>
      <origin xyz="0 0 0.00125" rpy="0 0 0" />
      <geometry>
        <mesh filename="package://darnet_description/meshes/darnet_stl/kepala/Intel_D415.stl" scale="0.001 0.001 0.001" />
      </geometry>
      <material name="grey" /> <!-- unfortunately you cant give color to stl files in gazebo -->
    </visual>
    <collision>
      <origin xyz="0 0 0.00125" rpy="0 0 0" /> <!-- in radians -->
      <geometry>
        <mesh filename="package://darnet_description/meshes/darnet_stl/kepala/Intel_D415.stl" scale="0.001 0.001 0.001" />
      </geometry>
    </collision>
    <inertial>
      <origin xyz="0.038 0.010 0.0" rpy="0 0 0" />
      <mass value="0.072" /> <!-- in kg -->
      <!--  -->
      <inertia
                ixx="1.0609e-3" 
                ixy="-1e-3" 
                ixz="-1e-3"
                iyy="5.0409e-3" 
                iyz="-1e-3"
                izz="1.0609e-3" />
    </inertial>
  </link>
  
  
  
  
  <joint name="camera_holder_to_camera_lock" type="fixed">
        <parent link="camera_holder"/>
        <child link="camera_lock"/>
        <origin rpy="0 0 0" xyz="0.0155 0.008292 0.006920"/>
    </joint>
    
    <link name="camera_lock">
    <visual>
      <origin xyz="-0.031 0 -0.0015" rpy="1.57 0 1.57" />
      <geometry>
        <mesh filename="package://darnet_description/meshes/darnet_stl/kepala/camera_lock.stl" scale="0.001 0.001 0.001" />
      </geometry>
      <material name="black" /> <!-- unfortunately you cant give color to stl files in gazebo -->
    </visual>
    <collision>
      <origin xyz="-0.031 0 -0.0015" rpy="1.57 0 1.57" /> <!-- in radians -->
      <geometry>
        <mesh filename="package://darnet_description/meshes/darnet_stl/kepala/camera_lock.stl" scale="0.001 0.001 0.001" />
      </geometry>
    </collision>
    <inertial>
      <origin xyz="0.020 0.015 0.0" rpy="0 0 0" />
      <mass value="0.036" /> <!-- in kg -->
      <!--  -->
      <inertia
                ixx="1.0609e-3" 
                ixy="-1e-3" 
                ixz="1e-3"
                iyy="5.0409e-3" 
                iyz="1e-3"
                izz="1.0609e-3" />
    </inertial>
  </link>
  
  
  <!-- ***************************************************************************** -->
  
  <!-- ********************************* Tangan kanan ****************************** -->
  
  
  <joint name="BadanAtasRevisi_to_MX-28AT_AR_1" type="fixed">
        <parent link="BadanAtasRevisi"/>
        <child link="MX-28AT_AR_1"/>
        <origin rpy="0 1.57 0" xyz="-0.013727 0.021073 -0.0825"/>
    </joint>
    
    
   <link name="MX-28AT_AR_1">
    <visual>
      <origin xyz="0 0 0" rpy="0 0 -1.57" />
      <geometry>
        <mesh filename="package://darnet_description/meshes/darnet_stl/tangan_kanan/MX-28AT_AR.stl" scale="0.001 0.001 0.001" />
      </geometry>
      <material name="grey" /> <!-- unfortunately you cant give color to stl files in gazebo -->
    </visual>
    <collision>
      <origin xyz="0 0 0" rpy="0 0 -1.57" /> <!-- in radians -->
      <geometry>
        <mesh filename="package://darnet_description/meshes/darnet_stl/tangan_kanan/MX-28AT_AR.stl" scale="0.001 0.001 0.001" />
      </geometry>
    </collision>
    <inertial>
      <origin xyz="0.0 -0.011 0.0" rpy="0 0 0" />
      <mass value="0.072" /> <!-- in kg -->
      <!--  -->
      <inertia
                ixx="1.0609e-3" 
                ixy="1e-3" 
                ixz="-1e-3"
                iyy="5.0409e-3" 
                iyz="-1e-3"
                izz="5.865e-3" />
    </inertial>
  </link>
  
  
    
    <joint name="MX-28AT_AR_1_to_10_FR07_H102" type="revolute">
        <parent link="MX-28AT_AR_1"/>
        <child link="10_FR07_H102"/>
        <origin rpy="0 0 0" xyz="0 0 0"/>
        <axis xyz="0 0 1"/>
        <limit effort="1.4" lower="-2.15" upper="1.15" velocity="6.96"/>
        <dynamics damping="0.0" friction="0.0"/>
    </joint>
    
    
   <link name="10_FR07_H102">
    <visual>
      <origin xyz="-0.082074 0.005 0.0508" rpy="1.57 0 0" />
      <geometry>
        <mesh filename="package://darnet_description/meshes/darnet_stl/tangan_kanan/10_FR07_H102.stl" scale="0.001 0.001 0.001" />
      </geometry>
      <material name="black" /> <!-- unfortunately you cant give color to stl files in gazebo -->
    </visual>
    <collision>
      <origin xyz="-0.082074 0.005 0.0508" rpy="1.57 0 0" /> <!-- in radians -->
      <geometry>
        <mesh filename="package://darnet_description/meshes/darnet_stl/tangan_kanan/10_FR07_H102.stl" scale="0.001 0.001 0.001" />
      </geometry>
    </collision>
    <inertial>
      <origin xyz="0.0 -0.008 0.022" rpy="0 0 0" />
      <mass value="0.04" /> <!-- in kg -->
      <!--  -->
      <inertia
                ixx="1.0609e-3" 
                ixy="1e-3" 
                ixz="-1e-3"
                iyy="5.0409e-3" 
                iyz="1e-3"
                izz="5.865e-3" />
    </inertial>
  </link>
  
  
  
  <joint name="10_FR07_H102_to_MX-28AT_AR_3" type="revolute">
        <parent link="10_FR07_H102"/>
        <child link="MX-28AT_AR_3"/>
        <origin rpy="0 1.57 0" xyz="0.000274 -0.015998 0.045"/>
        <axis xyz="0 0 1"/>
        <limit effort="1.4" lower="-2.15" upper="0" velocity="6.96"/>
        <dynamics damping="0.0" friction="0.0"/>
    </joint>
    
    
   <link name="MX-28AT_AR_3">
    <visual>
      <origin xyz="0 0 0" rpy="0 0 0" />
      <geometry>
        <mesh filename="package://darnet_description/meshes/darnet_stl/tangan_kanan/MX-28AT_AR.stl" scale="0.001 0.001 0.001" />
      </geometry>
      <material name="grey" /> <!-- unfortunately you cant give color to stl files in gazebo -->
    </visual>
    <collision>
      <origin xyz="0 0 0" rpy="0 0 0" /> <!-- in radians -->
      <geometry>
        <mesh filename="package://darnet_description/meshes/darnet_stl/tangan_kanan/MX-28AT_AR.stl" scale="0.001 0.001 0.001" />
      </geometry>
    </collision>
    <inertial>
      <origin xyz="0.0 -0.011 0.0" rpy="0 0 0" />
      <mass value="0.072" /> <!-- in kg -->
      <!--  -->
      <inertia
                ixx="1.0609e-3" 
                ixy="1e-3" 
                ixz="-1e-3"
                iyy="5.0409e-3" 
                iyz="-1e-3"
                izz="5.865e-3" />
    </inertial>
  </link>
  
  
  
  
  <joint name="MX-28AT_AR_3_to_14_FR07_S101" type="fixed">
        <parent link="MX-28AT_AR_3"/>
        <child link="14_FR07_S101"/>
        <origin rpy="-1.57 1.57 0" xyz="-0.234767 -0.009179 -0.036848"/>
    </joint>
    
    
   <link name="14_FR07_S101">
    <visual>
      <origin xyz="0 -0.0008 -0.01145" rpy="0 3.14 0" />
      <geometry>
        <mesh filename="package://darnet_description/meshes/darnet_stl/tangan_kanan/14_FR07_S101.stl" scale="0.001 0.001 0.001" />
      </geometry>
      <material name="black" /> <!-- unfortunately you cant give color to stl files in gazebo -->
    </visual>
    <collision>
      <origin xyz="0 -0.0008 -0.01145" rpy="0 3.14 0" /> <!-- in radians -->
      <geometry>
        <mesh filename="package://darnet_description/meshes/darnet_stl/tangan_kanan/14_FR07_S101.stl" scale="0.001 0.001 0.001" />
      </geometry>
    </collision>
    <inertial>
      <origin xyz="-0.037 -0.238 0.019 " rpy="0 0 0" /> <!-- based on joint, not link -->
      <mass value="0.012" /> <!-- in kg -->
      <!--  -->
      <inertia
                ixx="1.0609e-3" 
                ixy="1e-3" 
                ixz="-1e-3"
                iyy="5.0409e-3" 
                iyz="1e-3"
                izz="5.865e-3" />
    </inertial>
  </link>
  
  
  
  <joint name="14_FR07_S101_to_Hex_Spacer_MF_M3_L40mm_1" type="fixed">
        <parent link="14_FR07_S101"/>
        <child link="Hex_Spacer_MF_M3_L40mm_1"/>
        <origin rpy="0 0 0" xyz="-0.209989 -0.214168 -0.068704"/>
    </joint>
    
    
   <link name="Hex_Spacer_MF_M3_L40mm_1">
    <visual>
      <origin xyz="0.0008 -0.016895 -0.0038" rpy="3.14 0 0" />
      <geometry>
        <mesh filename="package://darnet_description/meshes/darnet_stl/tangan_kanan/Hex_Spacer_MF_M3_L40mm.stl" scale="0.001 0.001 0.001" />
      </geometry>
      <material name="grey" /> <!-- unfortunately you cant give color to stl files in gazebo -->
    </visual>
    <collision>
      <origin xyz="0.0008 -0.016895 -0.0038" rpy="3.14 0 0" /> <!-- in radians -->
      <geometry>
        <mesh filename="package://darnet_description/meshes/darnet_stl/tangan_kanan/Hex_Spacer_MF_M3_L40mm.stl" scale="0.001 0.001 0.001" />
      </geometry>
    </collision>
    <inertial>
      <origin xyz="0.182460 -0.012334 0.016262" rpy="0 0 0" /> <!-- based on joint as the origin, not link -->
      <mass value="0.01" /> <!-- in kg -->
      <!--  -->
      <inertia
                ixx="1.0609e-3" 
                ixy="1e-3" 
                ixz="-1e-3"
                iyy="5.0409e-3" 
                iyz="1e-3"
                izz="5.865e-3" />
    </inertial>
  </link>
  
  <joint name="14_FR07_S101_to_Hex_Spacer_MF_M3_L40mm_2" type="fixed">
        <parent link="14_FR07_S101"/>
        <child link="Hex_Spacer_MF_M3_L40mm_2"/>
        <origin rpy="0 0 0" xyz="-0.209989 -0.214168 -0.068704"/>
    </joint>
    
    
   <link name="Hex_Spacer_MF_M3_L40mm_2">
    <visual>
      <origin xyz="0.0008 -0.0325 -0.0038" rpy="3.14 0 0" />
      <geometry>
        <mesh filename="package://darnet_description/meshes/darnet_stl/tangan_kanan/Hex_Spacer_MF_M3_L40mm.stl" scale="0.001 0.001 0.001" />
      </geometry>
      <material name="grey" /> <!-- unfortunately you cant give color to stl files in gazebo -->
    </visual>
    <collision>
      <origin xyz="0.0008 -0.0325 -0.0038" rpy="3.14 0 0" /> <!-- in radians -->
      <geometry>
        <mesh filename="package://darnet_description/meshes/darnet_stl/tangan_kanan/Hex_Spacer_MF_M3_L40mm.stl" scale="0.001 0.001 0.001" />
      </geometry>
    </collision>
    <inertial>
      <origin xyz="0.182736 -0.029046 0.015383" rpy="0 0 0" /> <!-- based on joint, not link -->
      <mass value="0.01" /> <!-- in kg -->
      <!--  -->
      <inertia
                ixx="1.0609e-3" 
                ixy="1e-3" 
                ixz="-1e-3"
                iyy="5.0409e-3" 
                iyz="1e-3"
                izz="5.865e-3" />
    </inertial>
  </link>
  
  
  <joint name="14_FR07_S101_to_Hex_Spacer_MF_M3_L40mm_3" type="fixed">
        <parent link="14_FR07_S101"/>
        <child link="Hex_Spacer_MF_M3_L40mm_3"/>
        <origin rpy="0 0 0" xyz="-0.209989 -0.214168 -0.068704"/>
    </joint>
    
    
   <link name="Hex_Spacer_MF_M3_L40mm_3">
    <visual>
      <origin xyz="-0.01475 -0.0325 -0.0038" rpy="3.14 0 0" />
      <geometry>
        <mesh filename="package://darnet_description/meshes/darnet_stl/tangan_kanan/Hex_Spacer_MF_M3_L40mm.stl" scale="0.001 0.001 0.001" />
      </geometry>
      <material name="grey" /> <!-- unfortunately you cant give color to stl files in gazebo -->
    </visual>
    <collision>
      <origin xyz="-0.01475 -0.0325 -0.0038" rpy="3.14 0 0" /> <!-- in radians -->
      <geometry>
        <mesh filename="package://darnet_description/meshes/darnet_stl/tangan_kanan/Hex_Spacer_MF_M3_L40mm.stl" scale="0.001 0.001 0.001" />
      </geometry>
    </collision>
    <inertial>
      <origin xyz="0.166892 -0.027869 0.015715" rpy="0 0 0" /> <!-- based on joint, not link -->
      <mass value="0.01" /> <!-- in kg -->
      <!--  -->
      <inertia
                ixx="1.0609e-3" 
                ixy="1e-3" 
                ixz="-1e-3"
                iyy="5.0409e-3" 
                iyz="1e-3"
                izz="5.865e-3" />
    </inertial>
  </link>
  
  
  <joint name="14_FR07_S101_to_Hex_Spacer_MF_M3_L40mm_4" type="fixed">
        <parent link="14_FR07_S101"/>
        <child link="Hex_Spacer_MF_M3_L40mm_4"/>
        <origin rpy="0 0 0" xyz="-0.209989 -0.214168 -0.068704"/>
    </joint>
    
    
   <link name="Hex_Spacer_MF_M3_L40mm_4">
    <visual>
      <origin xyz="-0.01475 -0.016895 -0.0038" rpy="3.14 0 0" />
      <geometry>
        <mesh filename="package://darnet_description/meshes/darnet_stl/tangan_kanan/Hex_Spacer_MF_M3_L40mm.stl" scale="0.001 0.001 0.001" />
      </geometry>
      <material name="grey" /> <!-- unfortunately you cant give color to stl files in gazebo -->
    </visual>
    <collision>
      <origin xyz="-0.01475 -0.016895 -0.0038" rpy="3.14 0 0" /> <!-- in radians -->
      <geometry>
        <mesh filename="package://darnet_description/meshes/darnet_stl/tangan_kanan/Hex_Spacer_MF_M3_L40mm.stl" scale="0.001 0.001 0.001" />
      </geometry>
    </collision>
    <inertial>
      <origin xyz="0.161919 -0.011986 0.016632" rpy="0 0 0" /> <!-- based on joint, not link -->
      <mass value="0.01" /> <!-- in kg -->
      <!--  -->
      <inertia
                ixx="1.0609e-3" 
                ixy="1e-3" 
                ixz="-1e-3"
                iyy="5.0409e-3" 
                iyz="1e-3"
                izz="5.865e-3" />
    </inertial>
  </link>
  
  
  
  <joint name="14_FR07_S101_to_14_FR07_S101_2" type="fixed">
        <parent link="14_FR07_S101"/>
        <child link="14_FR07_S101_2"/>
        <origin rpy="0 0 -1.57" xyz="0.199382 -0.196541 -0.095821"/>
    </joint>
    
    
   <link name="14_FR07_S101_2">
    <visual>
      <origin xyz="0.005175 0.0016 0.00225" rpy="0 0 0" />
      <geometry>
        <mesh filename="package://darnet_description/meshes/darnet_stl/tangan_kanan/14_FR07_S101.stl" scale="0.001 0.001 0.001" />
      </geometry>
      <material name="black" /> <!-- unfortunately you cant give color to stl files in gazebo -->
    </visual>
    <collision>
      <origin xyz="0.005175 0.0016 0.00225" rpy="0 0 0" /> <!-- in radians -->
      <geometry>
        <mesh filename="package://darnet_description/meshes/darnet_stl/tangan_kanan/14_FR07_S101.stl" scale="0.001 0.001 0.001" />
      </geometry>
    </collision>
    <inertial>
      <origin xyz="0.037968 -0.237665 0.021611" rpy="0 0 0" /> <!-- based on joint, not link -->
      <mass value="0.012" /> <!-- in kg -->
      <!--  -->
      <inertia
                ixx="1.0609e-3" 
                ixy="1e-3" 
                ixz="-1e-3"
                iyy="5.0409e-3" 
                iyz="1e-3"
                izz="5.865e-3" />
    </inertial>
  </link>
  
  
  
  
  
  <joint name="14_FR07_S101_2_to_MX-28AT_AR_5" type="fixed">
        <parent link="14_FR07_S101_2"/>
        <child link="MX-28AT_AR_5"/>
        <origin rpy="1.57 0 0" xyz="0.042199 -0.253346 0.002331"/>
    </joint>
    
    <!-- 0.00525 -0.0001 -0.00165 -->
   <link name="MX-28AT_AR_5">
    <visual>
      <origin xyz="0 0 0" rpy="1.57 0 -1.57" />
      <geometry>
        <mesh filename="package://darnet_description/meshes/darnet_stl/tangan_kanan/MX-28AT_AR.stl" scale="0.001 0.001 0.001" />
      </geometry>
      <material name="grey" /> <!-- unfortunately you cant give color to stl files in gazebo -->
    </visual>
    <collision>
      <origin xyz="0 0 0" rpy="1.57 0 -1.57" /> <!-- in radians -->
      <geometry>
        <mesh filename="package://darnet_description/meshes/darnet_stl/tangan_kanan/MX-28AT_AR.stl" scale="0.001 0.001 0.001" />
      </geometry>
    </collision>
    <inertial>
      <origin xyz="0.0 -0.011 0.0" rpy="0 0 0" />
      <mass value="0.072" /> <!-- in kg -->
      <!--  -->
      <inertia
                ixx="1.0609e-3" 
                ixy="1e-3" 
                ixz="-1e-3"
                iyy="5.0409e-3" 
                iyz="-1e-3"
                izz="5.865e-3" />
    </inertial>
  </link>
  
  
  
  
  
  <joint name="MX-28AT_AR_5_to_10_FR07_H102_2" type="revolute">
        <parent link="MX-28AT_AR_5"/>
        <child link="10_FR07_H102_2"/>
        <origin rpy="0 -1.57 0" xyz="0 0 0"/>
        <axis xyz="0 0 1"/>
        <limit effort="1.4" lower="-0.30" upper="02.15" velocity="6.96"/>
        <dynamics damping="0.0" friction="0.0"/>
    </joint>
    
   <link name="10_FR07_H102_2">
    <visual>
      <origin xyz="-0.02105 0.00579 0.0820" rpy="0 1.57 0" />
      <geometry>
        <mesh filename="package://darnet_description/meshes/darnet_stl/tangan_kanan/10_FR07_H102.stl" scale="0.001 0.001 0.001" />
      </geometry>
      <material name="black" /> <!-- unfortunately you cant give color to stl files in gazebo -->
    </visual>
    <collision>
      <origin xyz="-0.02105 0.00579 0.0820" rpy="0 1.57 0" /> <!-- in radians -->
      <geometry>
        <mesh filename="package://darnet_description/meshes/darnet_stl/tangan_kanan/10_FR07_H102.stl" scale="0.001 0.001 0.001" />
      </geometry>
    </collision>
    <inertial>
      <origin xyz="0.0 -0.008 0.022" rpy="0 0 0" />
      <mass value="0.04" /> <!-- in kg -->
      <!--  -->
      <inertia
                ixx="1.0609e-3" 
                ixy="1e-3" 
                ixz="-1e-3"
                iyy="5.0409e-3" 
                iyz="1e-3"
                izz="5.865e-3" />
    </inertial>
  </link>
  
  
  
  
  
  
  <joint name="10_FR07_H102_2_to_FP04-F9" type="fixed">
        <parent link="10_FR07_H102_2"/>
        <child link="FP04-F9"/>
        <origin rpy="-1.57 -1.57 0" xyz="-0.016143 -0.023728 0.013744"/>
    </joint>
    
    <!-- 0.00525 -0.0001 -0.00165 -->
   <link name="FP04-F9">
    <visual>
      <origin xyz="-0.001 0 0" rpy="0 0 0" /> <!-- xyz w.r.t. joint's xyz -->
      <geometry>
        <mesh filename="package://darnet_description/meshes/darnet_stl/tangan_kanan/FP04-F9.stl" scale="0.001 0.001 0.001" />
      </geometry>
      <material name="grey" /> <!-- unfortunately you cant give color to stl files in gazebo -->
    </visual>
    <collision>
      <origin xyz="-0.001 0 0" rpy="0 0 0" /> <!-- in radians -->
      <geometry>
        <mesh filename="package://darnet_description/meshes/darnet_stl/tangan_kanan/FP04-F9.stl" scale="0.001 0.001 0.001" />
      </geometry>
    </collision>
    <inertial>
      <origin xyz="-0.007 0 -0.009" rpy="0 0 0" /> 
      <mass value="0.005" /> <!-- in kg -->
      <!--  -->
      <inertia
                ixx="1.0609e-3" 
                ixy="1e-3" 
                ixz="-1e-3"
                iyy="5.0409e-3" 
                iyz="-1e-3"
                izz="5.865e-3" />
    </inertial>
  </link>
  
  
  
  
  
  <joint name="FP04-F9_to_Tangan" type="fixed">
        <parent link="FP04-F9"/>
        <child link="Tangan"/>
        <origin rpy="0 -1.57 0" xyz="0.0041 -0.018 0.050175"/>
    </joint>
    
    <!-- 0.00525 -0.0001 -0.00165 -->
   <link name="Tangan">
    <visual>
      <origin xyz="0 0 0" rpy="0 0 0" /> <!-- xyz w.r.t. joint's xyz -->
      <geometry>
        <mesh filename="package://darnet_description/meshes/darnet_stl/tangan_kanan/Tangan.stl" scale="0.001 0.001 0.001" />
      </geometry>
      <material name="grey" /> <!-- unfortunately you cant give color to stl files in gazebo -->
    </visual>
    <collision>
      <origin xyz="0 0 0" rpy="0 0 0" /> <!-- in radians -->
      <geometry>
        <mesh filename="package://darnet_description/meshes/darnet_stl/tangan_kanan/Tangan.stl" scale="0.001 0.001 0.001" />
      </geometry>
    </collision>
    <inertial>
      <origin xyz="-0.107 0.018 0.003" rpy="0 0 0" /> 
      <mass value="0.02" /> <!-- in kg -->
      <!--  -->
      <inertia
                ixx="1.0609e-3" 
                ixy="1e-3" 
                ixz="1e-3"
                iyy="5.0409e-3" 
                iyz="-1e-3"
                izz="5.865e-3" />
    </inertial>
  </link>
  
   <!-- ***************************************************************************** -->
  
  <!-- ********************************* Kaki kanan ****************************** -->
  
  <joint name="BadanBawahRevisi_to_SpaceMX64" type="fixed">
        <parent link="BadanBawahRevisi"/>
        <child link="SpaceMX64"/>
        <origin rpy="0 3.14 0" xyz="-0.040583 -0.005 -0.101222"/>
    </joint>
    
    <!-- 0.00525 -0.0001 -0.00165 -->
   <link name="SpaceMX64">
    <visual>
      <origin xyz="0 0 0" rpy="0 0 0" /> <!-- xyz w.r.t. joint's xyz -->
      <geometry>
        <mesh filename="package://darnet_description/meshes/darnet_stl/kaki_kanan/SpaceMX64.stl" scale="0.001 0.001 0.001" />
      </geometry>
      <material name="grey" /> <!-- unfortunately you cant give color to stl files in gazebo -->
    </visual>
    <collision>
      <origin xyz="0 0 0" rpy="0 0 0" /> <!-- in radians -->
      <geometry>
        <mesh filename="package://darnet_description/meshes/darnet_stl/kaki_kanan/SpaceMX64.stl" scale="0.001 0.001 0.001" />
      </geometry>
    </collision>
    <inertial>
      <origin xyz="-0.02 0.003 -0.028" rpy="0 0 0" /> 
      <mass value="0.029" /> <!-- in kg -->
      <!--  -->
      <inertia
                ixx="1.0609e-3" 
                ixy="1e-3" 
                ixz="-1e-3"
                iyy="5.0409e-3" 
                iyz="1e-3"
                izz="5.865e-3" />
    </inertial>
  </link>
  
  
  
  
  
  <joint name="SpaceMX64_to_MX-64T_7" type="fixed">
        <parent link="SpaceMX64"/>
        <child link="MX-64T_7"/>
        <origin rpy="1.57 0 0" xyz="-0.020283 -0.017 -0.018222"/>
    </joint>
    
    <!-- 0.00525 -0.0001 -0.00165 -->
   <link name="MX-64T_7">
    <visual>
      <origin xyz="0 0 0" rpy="0 0 0" /> <!-- xyz w.r.t. joint's xyz -->
      <geometry>
        <mesh filename="package://darnet_description/meshes/darnet_stl/kaki_kanan/MX-64T.stl" scale="0.001 0.001 0.001" />
      </geometry>
      <material name="grey" /> <!-- unfortunately you cant give color to stl files in gazebo -->
    </visual>
    <collision>
      <origin xyz="0 0 0" rpy="0 0 0" /> <!-- in radians -->
      <geometry>
        <mesh filename="package://darnet_description/meshes/darnet_stl/kaki_kanan/MX-64T.stl" scale="0.001 0.001 0.001" />
      </geometry>
    </collision>
    <inertial>
      <origin xyz="0 -0.015 0" rpy="0 0 0" /> 
      <mass value="0.135" /> <!-- in kg -->
      <!--  -->
      <inertia
                ixx="1.0609e-3" 
                ixy="1e-3" 
                ixz="1e-3"
                iyy="5.0409e-3" 
                iyz="1e-3"
                izz="5.865e-3" />
    </inertial>
  </link>
  
  
  
  
  
  <joint name="MX-64T_7_to_PahaAtas3D" type="revolute">
        <parent link="MX-64T_7"/>
        <child link="PahaAtas3D"/>
        <origin rpy="0 0 0" xyz="0 0 0"/>
        <axis xyz="0 0 1"/>
        <limit effort="1.4" lower="-2.15" upper="2.15" velocity="6.96"/>
        <dynamics damping="0.0" friction="0.0"/>
    </joint>
    
   <link name="PahaAtas3D">
    <visual>
      <origin xyz="0.013934 0.024617 0.0235" rpy="1.57 0 1.57" />
      <geometry>
        <mesh filename="package://darnet_description/meshes/darnet_stl/kaki_kanan/PahaAtas3D.stl" scale="0.001 0.001 0.001" />
      </geometry>
      <material name="black" /> <!-- unfortunately you cant give color to stl files in gazebo -->
    </visual>
    <collision>
      <origin xyz="0.013934 0.024617 0.0235" rpy="1.57 0 1.57" /> <!-- in radians -->
      <geometry>
        <mesh filename="package://darnet_description/meshes/darnet_stl/kaki_kanan/PahaAtas3D.stl" scale="0.001 0.001 0.001" />
      </geometry>
    </collision>
    <inertial> <!-- in inventor: -0.028 -0.014 0.010 -->
      <origin xyz="-0.0014066 0.010617 0.0335" rpy="0 0 0" />
      <mass value="0.068" /> <!-- in kg -->
      <!--  -->
      <inertia
                ixx="1.0609e-3" 
                ixy="1e-3" 
                ixz="-1e-3"
                iyy="5.0409e-3" 
                iyz="1e-3"
                izz="5.865e-3" />
    </inertial>
  </link>
  
  
  
  
  
  
  <joint name="PahaAtas3D_to_MX-64T_9" type="revolute">
        <parent link="PahaAtas3D"/>
        <child link="MX-64T_9"/>
        <origin rpy="-1.57 0 0" xyz="0.000157 -0.058353 0.062045"/>
        <axis xyz="0 0 1"/>
        <limit effort="1.4" lower="-1.57" upper="0.25" velocity="6.96"/>
        <dynamics damping="0.0" friction="0.0"/>
    </joint>
    
    <!-- 0.00525 -0.0001 -0.00165 -->
   <link name="MX-64T_9">
    <visual>
      <origin xyz="0 0 0" rpy="0 0 0" /> <!-- xyz w.r.t. joint's xyz -->
      <geometry>
        <mesh filename="package://darnet_description/meshes/darnet_stl/kaki_kanan/MX-64T.stl" scale="0.001 0.001 0.001" />
      </geometry>
      <material name="grey" /> <!-- unfortunately you cant give color to stl files in gazebo -->
    </visual>
    <collision>
      <origin xyz="0 0 0" rpy="0 0 0" /> <!-- in radians -->
      <geometry>
        <mesh filename="package://darnet_description/meshes/darnet_stl/kaki_kanan/MX-64T.stl" scale="0.001 0.001 0.001" />
      </geometry>
    </collision>
    <inertial>
      <origin xyz="0 -0.015 0" rpy="0 0 0" /> 
      <mass value="0.135" /> <!-- in kg -->
      <!--  -->
      <inertia
                ixx="1.0609e-3" 
                ixy="1e-3" 
                ixz="1e-3"
                iyy="5.0409e-3" 
                iyz="1e-3"
                izz="5.865e-3" />
    </inertial>
  </link>
  
  
  
  
  
  
  <joint name="MX-64T_9_to_SambunganServo_Revision_2" type="fixed">
        <parent link="MX-64T_9"/>
        <child link="SambunganServo_Revision_2"/>
        <origin rpy="1.57 0 1.57" xyz="-0.019869 -0.015233 0.016947"/>
    </joint>
    
   <link name="SambunganServo_Revision_2">
    <visual>
      <origin xyz="0 0 0" rpy="0 0 0" /> <!-- xyz w.r.t. joint's xyz -->
      <geometry>
        <mesh filename="package://darnet_description/meshes/darnet_stl/kaki_kanan/SambunganServo_Revision.stl" scale="0.001 0.001 0.001" />
      </geometry>
      <material name="grey" /> <!-- unfortunately you cant give color to stl files in gazebo -->
    </visual>
    <collision>
      <origin xyz="0 0 0" rpy="0 0 0" /> <!-- in radians -->
      <geometry>
        <mesh filename="package://darnet_description/meshes/darnet_stl/kaki_kanan/SambunganServo_Revision.stl" scale="0.001 0.001 0.001" />
      </geometry>
    </collision>
    <inertial>
      <origin xyz="-0.014 0.011 0.002" rpy="0 0 0" /> 
      <mass value="0.009" /> <!-- in kg -->
      <!--  -->
      <inertia
                ixx="1.0609e-3" 
                ixy="1e-3" 
                ixz="1e-3"
                iyy="5.0409e-3" 
                iyz="-1e-3"
                izz="5.865e-3" />
    </inertial>
  </link>
  
  
  
  
  
  <joint name="MX-64T_9_to_SambunganServo_Revision_1" type="fixed">
        <parent link="MX-64T_9"/>
        <child link="SambunganServo_Revision_1"/>
        <origin rpy="1.57 0 -1.57" xyz="0.020456 -0.042763 0.017055"/>
    </joint>
    
   <link name="SambunganServo_Revision_1">
    <visual>
      <origin xyz="0 0 0" rpy="0 0 0" /> <!-- xyz w.r.t. joint's xyz -->
      <geometry>
        <mesh filename="package://darnet_description/meshes/darnet_stl/kaki_kanan/SambunganServo_Revision.stl" scale="0.001 0.001 0.001" />
      </geometry>
      <material name="grey" /> <!-- unfortunately you cant give color to stl files in gazebo -->
    </visual>
    <collision>
      <origin xyz="0 0 0" rpy="0 0 0" /> <!-- in radians -->
      <geometry>
        <mesh filename="package://darnet_description/meshes/darnet_stl/kaki_kanan/SambunganServo_Revision.stl" scale="0.001 0.001 0.001" />
      </geometry>
    </collision>
    <inertial>
      <origin xyz="-0.014 0.011 0.002" rpy="0 0 0" /> 
      <mass value="0.009" /> <!-- in kg -->
      <!--  -->
      <inertia
                ixx="1.0609e-3" 
                ixy="1e-3" 
                ixz="1e-3"
                iyy="5.0409e-3" 
                iyz="-1e-3"
                izz="5.865e-3" />
    </inertial>
  </link>
  
  
  
  
  
  
  <joint name="MX-64T_9_to_MX-64T_11" type="fixed">
        <parent link="MX-64T_9"/>
        <child link="MX-64T_11"/>
        <origin rpy="0 1.57 0" xyz="-0.000139 0 0.0517"/>
    </joint>
    
    <!-- 0.00525 -0.0001 -0.00165 -->
   <link name="MX-64T_11">
    <visual>
      <origin xyz="0 0 0" rpy="0 0 0" /> <!-- xyz w.r.t. joint's xyz -->
      <geometry>
        <mesh filename="package://darnet_description/meshes/darnet_stl/kaki_kanan/MX-64T.stl" scale="0.001 0.001 0.001" />
      </geometry>
      <material name="grey" /> <!-- unfortunately you cant give color to stl files in gazebo -->
    </visual>
    <collision>
      <origin xyz="0 0 0" rpy="0 0 0" /> <!-- in radians -->
      <geometry>
        <mesh filename="package://darnet_description/meshes/darnet_stl/kaki_kanan/MX-64T.stl" scale="0.001 0.001 0.001" />
      </geometry>
    </collision>
    <inertial>
      <origin xyz="0 -0.015 0" rpy="0 0 0" /> 
      <mass value="0.135" /> <!-- in kg -->
      <!--  -->
      <inertia
                ixx="1.0609e-3" 
                ixy="1e-3" 
                ixz="1e-3"
                iyy="5.0409e-3" 
                iyz="1e-3"
                izz="5.865e-3" />
    </inertial>
  </link>
  
  
  
  
  
  
   <joint name="MX-64T_11_to_FR05-S101" type="fixed">
        <parent link="MX-64T_11"/>
        <child link="FR05-S101"/>
        <origin rpy="3.14 0 1.57" xyz="-0.024 0 -0.000065"/>
    </joint>
    
    <!-- 0.00525 -0.0001 -0.00165 -->
   <link name="FR05-S101">
    <visual>
      <origin xyz="0 0 0" rpy="0 0 0" /> <!-- xyz w.r.t. joint's xyz -->
      <geometry>
        <mesh filename="package://darnet_description/meshes/darnet_stl/kaki_kanan/FR05-S101.stl" scale="0.001 0.001 0.001" />
      </geometry>
      <material name="grey" /> <!-- unfortunately you cant give color to stl files in gazebo -->
    </visual>
    <collision>
      <origin xyz="0 0 0" rpy="0 0 0" /> <!-- in radians -->
      <geometry>
        <mesh filename="package://darnet_description/meshes/darnet_stl/kaki_kanan/FR05-S101.stl" scale="0.001 0.001 0.001" />
      </geometry>
    </collision>
    <inertial>
      <origin xyz="-0.001 0.003 0" rpy="0 0 0" /> 
      <mass value="0.022" /> <!-- in kg -->
      <!--  -->
      <inertia
                ixx="1.0609e-3" 
                ixy="1e-3" 
                ixz="1e-3"
                iyy="5.0409e-3" 
                iyz="1e-3"
                izz="5.865e-3" />
    </inertial>
  </link>
  
  
  
  
  
  <joint name="FR05-S101_to_FR05-F101" type="fixed">
        <parent link="FR05-S101"/>
        <child link="FR05-F101"/>
        <origin rpy="1.57 0 0" xyz="0 0 0"/>
    </joint>
    
    <!-- 0.00525 -0.0001 -0.00165 -->
   <link name="FR05-F101">
    <visual>
      <origin xyz="0 0 0" rpy="0 0 0" /> <!-- xyz w.r.t. joint's xyz -->
      <geometry>
        <mesh filename="package://darnet_description/meshes/darnet_stl/kaki_kanan/FR05-F101.stl" scale="0.001 0.001 0.001" />
      </geometry>
      <material name="grey" /> <!-- unfortunately you cant give color to stl files in gazebo -->
    </visual>
    <collision>
      <origin xyz="0 0 0" rpy="0 0 0" /> <!-- in radians -->
      <geometry>
        <mesh filename="package://darnet_description/meshes/darnet_stl/kaki_kanan/FR05-F101.stl" scale="0.001 0.001 0.001" />
      </geometry>
    </collision>
    <inertial>
      <origin xyz="0 0 0.001" rpy="0 0 0" /> 
      <mass value="0.008" /> <!-- in kg -->
      <!--  -->
      <inertia
                ixx="1.0609e-3" 
                ixy="-1e-3" 
                ixz="1e-3"
                iyy="5.0409e-3" 
                iyz="1e-3"
                izz="5.865e-3" />
    </inertial>
  </link>
  
  
  
  <joint name="FR05-F101_to_HN05-i101" type="fixed">
        <parent link="FR05-F101"/>
        <child link="HN05-i101"/>
        <origin rpy="1.57 0 0" xyz="0 0.000016 0.0058"/>
    </joint>
    
    <!-- 0.00525 -0.0001 -0.00165 -->
   <link name="HN05-i101">
    <visual>
      <origin xyz="0 0 0" rpy="0 0 0" /> <!-- xyz w.r.t. joint's xyz -->
      <geometry>
        <mesh filename="package://darnet_description/meshes/darnet_stl/kaki_kanan/HN05-i101.stl" scale="0.001 0.001 0.001" />
      </geometry>
      <material name="grey" /> <!-- unfortunately you cant give color to stl files in gazebo -->
    </visual>
    <collision>
      <origin xyz="0 0 0" rpy="0 0 0" /> <!-- in radians -->
      <geometry>
        <mesh filename="package://darnet_description/meshes/darnet_stl/kaki_kanan/HN05-i101.stl" scale="0.001 0.001 0.001" />
      </geometry>
    </collision>
    <inertial>
      <origin xyz="0 -0.001 0" rpy="0 0 0" /> 
      <mass value="0.01" /> <!-- in kg -->
      <!--  -->
      <inertia
                ixx="1.0609e-3" 
                ixy="1e-3" 
                ixz="1e-3"
                iyy="5.0409e-3" 
                iyz="-1e-3"
                izz="5.865e-3" />
    </inertial>
  </link>
  
  
  
  
  
  
  <joint name="HN05-i101_to_MF128ZZ" type="fixed">
        <parent link="HN05-i101"/>
        <child link="MF128ZZ"/>
        <origin rpy="0 0 0" xyz="0 -0.001 0"/>
    </joint>
    
    <!-- 0.00525 -0.0001 -0.00165 -->
   <link name="MF128ZZ">
    <visual>
      <origin xyz="0 0 0" rpy="0 0 0" /> <!-- xyz w.r.t. joint's xyz -->
      <geometry>
        <mesh filename="package://darnet_description/meshes/darnet_stl/kaki_kanan/MF128ZZ.stl" scale="0.001 0.001 0.001" />
      </geometry>
      <material name="grey" /> <!-- unfortunately you cant give color to stl files in gazebo -->
    </visual>
    <collision>
      <origin xyz="0 0 0" rpy="0 0 0" /> <!-- in radians -->
      <geometry>
        <mesh filename="package://darnet_description/meshes/darnet_stl/kaki_kanan/MF128ZZ.stl" scale="0.001 0.001 0.001" />
      </geometry>
    </collision>
    <inertial>
      <origin xyz="0 0.002 0" rpy="0 0 0" /> 
      <mass value="0.002" /> <!-- in kg -->
      <!--  -->
      <inertia
                ixx="1.0609e-3" 
                ixy="-1e-3" 
                ixz="1e-3"
                iyy="5.0409e-3" 
                iyz="1e-3"
                izz="5.865e-3" />
    </inertial>
  </link>
  
  
  
  
  
  <joint name="MF128ZZ_to_RX64-CAP" type="fixed">
        <parent link="MF128ZZ"/>
        <child link="RX64-CAP"/>
        <origin rpy="-1.57 0 0" xyz="0 0.00468 -0.000013"/>
    </joint>
    
    <!-- 0.00525 -0.0001 -0.00165 -->
   <link name="RX64-CAP">
    <visual>
      <origin xyz="0 0 0" rpy="0 0 0" /> <!-- xyz w.r.t. joint's xyz -->
      <geometry>
        <mesh filename="package://darnet_description/meshes/darnet_stl/kaki_kanan/RX64-CAP.stl" scale="0.001 0.001 0.001" />
      </geometry>
      <material name="grey" /> <!-- unfortunately you cant give color to stl files in gazebo -->
    </visual>
    <collision>
      <origin xyz="0 0 0" rpy="0 0 0" /> <!-- in radians -->
      <geometry>
        <mesh filename="package://darnet_description/meshes/darnet_stl/kaki_kanan/RX64-CAP.stl" scale="0.001 0.001 0.001" />
      </geometry>
    </collision>
    <inertial>
      <origin xyz="0 0 0" rpy="0 0 0" /> 
      <mass value="0.001" /> <!-- in kg -->
      <!--  -->
      <inertia
                ixx="1.0609e-3" 
                ixy="-1e-3" 
                ixz="-1e-3"
                iyy="5.0409e-3" 
                iyz="-1e-3"
                izz="5.865e-3" />
    </inertial>
  </link>
  
  
  
  
  
  
  <joint name="MX-64T_11_to_PahaBawah" type="revolute">
        <parent link="MX-64T_11"/>
        <child link="PahaBawah"/>
        <origin rpy="0 0 0" xyz="0 0 0"/>
        <axis xyz="0 0 1"/>
        <limit effort="1.4" lower="-1.99" upper="0.55" velocity="6.96"/>
        <dynamics damping="0.0" friction="0.0"/>
    </joint>
    
   <link name="PahaBawah">
    <visual>
      <origin xyz="0.014 -0.0712 -0.021358" rpy="0 1.57 0" />
      <geometry>
        <mesh filename="package://darnet_description/meshes/darnet_stl/kaki_kanan/PahaBawah.stl" scale="0.001 0.001 0.001" />
      </geometry>
      <material name="black" /> <!-- unfortunately you cant give color to stl files in gazebo -->
    </visual>
    <collision>
      <origin xyz="0.014 -0.0712 -0.021358" rpy="0 1.57 0" /> <!-- in radians -->
      <geometry>
        <mesh filename="package://darnet_description/meshes/darnet_stl/kaki_kanan/PahaBawah.stl" scale="0.001 0.001 0.001" />
      </geometry>
    </collision>
    <inertial> <!-- in inventor: -0.014 0.024 -0.022 -->
      <origin xyz="0.0 -0.0472 0.0" rpy="0 0 0" />
      <mass value="0.077" /> <!-- in kg -->
      <!--  -->
      <inertia
                ixx="1.0609e-3" 
                ixy="1e-3" 
                ixz="-1e-3"
                iyy="5.0409e-3" 
                iyz="1e-3"
                izz="5.865e-3" />
    </inertial>
  </link>
  
  
  
  
  
  
  <joint name="PahaBawah_to_FR05-S101_2" type="fixed">
        <parent link="PahaBawah"/>
        <child link="FR05-S101_2"/>
        <origin rpy="0 0 3.14" xyz="0.0 -0.070987 0.00095"/>
    </joint>
    
    <!-- 0.00525 -0.0001 -0.00165 -->
   <link name="FR05-S101_2">
    <visual>
      <origin xyz="0 0 0" rpy="0 0 0" /> <!-- xyz w.r.t. joint's xyz -->
      <geometry>
        <mesh filename="package://darnet_description/meshes/darnet_stl/kaki_kanan/FR05-S101.stl" scale="0.001 0.001 0.001" />
      </geometry>
      <material name="black" /> <!-- unfortunately you cant give color to stl files in gazebo -->
    </visual>
    <collision>
      <origin xyz="0 0 0" rpy="0 0 0" /> <!-- in radians -->
      <geometry>
        <mesh filename="package://darnet_description/meshes/darnet_stl/kaki_kanan/FR05-S101.stl" scale="0.001 0.001 0.001" />
      </geometry>
    </collision>
    <inertial>
      <origin xyz="-0.001 0.003 0" rpy="0 0 0" /> 
      <mass value="0.022" /> <!-- in kg -->
      <!--  -->
      <inertia
                ixx="1.0609e-3" 
                ixy="1e-3" 
                ixz="1e-3"
                iyy="5.0409e-3" 
                iyz="1e-3"
                izz="5.865e-3" />
    </inertial>
  </link>
  
  
  
  
  
  <joint name="FR05-S101_2_to_MX-64T_13" type="fixed">
        <parent link="FR05-S101_2"/>
        <child link="MX-64T_13"/>
        <origin rpy="0 0 0" xyz="0.0 0.051990 0.000606"/>
    </joint>
    
    <!-- 0.00525 -0.0001 -0.00165 -->
   <link name="MX-64T_13">
    <visual>
      <origin xyz="0 0 0" rpy="0 0 0" /> <!-- xyz w.r.t. joint's xyz -->
      <geometry>
        <mesh filename="package://darnet_description/meshes/darnet_stl/kaki_kanan/MX-64T.stl" scale="0.001 0.001 0.001" />
      </geometry>
      <material name="grey" /> <!-- unfortunately you cant give color to stl files in gazebo -->
    </visual>
    <collision>
      <origin xyz="0 0 0" rpy="0 0 0" /> <!-- in radians -->
      <geometry>
        <mesh filename="package://darnet_description/meshes/darnet_stl/kaki_kanan/MX-64T.stl" scale="0.001 0.001 0.001" />
      </geometry>
    </collision>
    <inertial>
      <origin xyz="0 -0.015 0" rpy="0 0 0" /> 
      <mass value="0.135" /> <!-- in kg -->
      <!--  -->
      <inertia
                ixx="1.0609e-3" 
                ixy="1e-3" 
                ixz="1e-3"
                iyy="5.0409e-3" 
                iyz="1e-3"
                izz="5.865e-3" />
    </inertial>
  </link>
  
  
  
  
  
  <joint name="MX-64T_13_to_Tungkak" type="revolute">
        <parent link="MX-64T_13"/>
        <child link="Tungkak"/>
        <origin rpy="0 0 0" xyz="0 0 0"/>
        <axis xyz="0 0 1"/>
        <limit effort="1.4" lower="-0.25" upper="1.55" velocity="6.96"/>
        <dynamics damping="0.0" friction="0.0"/>
    </joint>
    
   <link name="Tungkak">
    <visual>
      <origin xyz="0.0255 0.059144 0.022854" rpy="-3.14 -1.57 0" />
      <geometry>
        <mesh filename="package://darnet_description/meshes/darnet_stl/kaki_kanan/Tungkak.stl" scale="0.001 0.001 0.001" />
      </geometry>
      <material name="black" /> <!-- unfortunately you cant give color to stl files in gazebo -->
    </visual>
    <collision>
      <origin xyz="0.0255 0.059144 0.022854" rpy="-3.14 -1.57 0" /> <!-- in radians -->
      <geometry>
        <mesh filename="package://darnet_description/meshes/darnet_stl/kaki_kanan/Tungkak.stl" scale="0.001 0.001 0.001" />
      </geometry>
    </collision>
    <inertial> <!-- in inventor: -0.015 -0.011 -0.022 --> <!-- setelah disamain koordinatnya -->
      <origin xyz="0.0105 0.048144 0.000854" rpy="0 0 0" />
      <mass value="0.159" /> <!-- in kg -->
      <!--  -->
      <inertia
                ixx="1.0609e-3" 
                ixy="1e-3" 
                ixz="-1e-3"
                iyy="5.0409e-3" 
                iyz="-1e-3"
                izz="5.865e-3" />
    </inertial>
  </link>
  
  
  
  
  
  <joint name="Tungkak_to_MX-64T_15" type="revolute">
        <parent link="Tungkak"/>
        <child link="MX-64T_15"/>
        <origin rpy="0 0 0" xyz="0.0 0.121113 0.001421"/>
        <axis xyz="0 0 1"/>
        <limit effort="1.4" lower="-1.57" upper="1.10" velocity="6.96"/>
        <dynamics damping="0.0" friction="0.0"/>
    </joint>
    
    <!-- 0.00525 -0.0001 -0.00165 -->
   <link name="MX-64T_15">
    <visual>
      <origin xyz="0 0 0" rpy="0 0 0" /> <!-- xyz w.r.t. joint's xyz -->
      <geometry>
        <mesh filename="package://darnet_description/meshes/darnet_stl/kaki_kanan/MX-64T.stl" scale="0.001 0.001 0.001" />
      </geometry>
      <material name="grey" /> <!-- unfortunately you cant give color to stl files in gazebo -->
    </visual>
    <collision>
      <origin xyz="0 0 0" rpy="0 0 0" /> <!-- in radians -->
      <geometry>
        <mesh filename="package://darnet_description/meshes/darnet_stl/kaki_kanan/MX-64T.stl" scale="0.001 0.001 0.001" />
      </geometry>
    </collision>
    <inertial>
      <origin xyz="0 -0.015 0" rpy="0 0 0" /> 
      <mass value="0.135" /> <!-- in kg -->
      <!--  -->
      <inertia
                ixx="1.0609e-3" 
                ixy="1e-3" 
                ixz="1e-3"
                iyy="5.0409e-3" 
                iyz="1e-3"
                izz="5.865e-3" />
    </inertial>
  </link>
  
  
  
  
  
  
  <joint name="MX-64T_15_to_SambunganServo_Revision_3" type="fixed">
        <parent link="MX-64T_15"/>
        <child link="SambunganServo_Revision_3"/>
        <origin rpy="0 0 -1.57" xyz="-0.03465 -0.043 -0.020404"/>
    </joint>
    
   <link name="SambunganServo_Revision_3">
    <visual>
      <origin xyz="0 0 0" rpy="0 0 0" /> <!-- xyz w.r.t. joint's xyz -->
      <geometry>
        <mesh filename="package://darnet_description/meshes/darnet_stl/kaki_kanan/SambunganServo_Revision.stl" scale="0.001 0.001 0.001" />
      </geometry>
      <material name="grey" /> <!-- unfortunately you cant give color to stl files in gazebo -->
    </visual>
    <collision>
      <origin xyz="0 0 0" rpy="0 0 0" /> <!-- in radians -->
      <geometry>
        <mesh filename="package://darnet_description/meshes/darnet_stl/kaki_kanan/SambunganServo_Revision.stl" scale="0.001 0.001 0.001" />
      </geometry>
    </collision>
    <inertial>
      <origin xyz="-0.014 0.011 0.002" rpy="0 0 0" /> 
      <mass value="0.009" /> <!-- in kg -->
      <!--  -->
      <inertia
                ixx="1.0609e-3" 
                ixy="1e-3" 
                ixz="1e-3"
                iyy="5.0409e-3" 
                iyz="-1e-3"
                izz="5.865e-3" />
    </inertial>
  </link>
  
  
  
  
  
  <joint name="MX-64T_15_to_SambunganServo_Revision_4" type="fixed">
        <parent link="MX-64T_15"/>
        <child link="SambunganServo_Revision_4"/>
        <origin rpy="3.14 0 1.57" xyz="-0.0347 -0.015 0.02"/>
    </joint>
    
   <link name="SambunganServo_Revision_4">
    <visual>
      <origin xyz="0 0 0" rpy="0 0 0" /> <!-- xyz w.r.t. joint's xyz -->
      <geometry>
        <mesh filename="package://darnet_description/meshes/darnet_stl/kaki_kanan/SambunganServo_Revision.stl" scale="0.001 0.001 0.001" />
      </geometry>
      <material name="grey" /> <!-- unfortunately you cant give color to stl files in gazebo -->
    </visual>
    <collision>
      <origin xyz="0 0 0" rpy="0 0 0" /> <!-- in radians -->
      <geometry>
        <mesh filename="package://darnet_description/meshes/darnet_stl/kaki_kanan/SambunganServo_Revision.stl" scale="0.001 0.001 0.001" />
      </geometry>
    </collision>
    <inertial>
      <origin xyz="-0.014 0.011 0.002" rpy="0 0 0" /> 
      <mass value="0.009" /> <!-- in kg -->
      <!--  -->
      <inertia
                ixx="1.0609e-3" 
                ixy="1e-3" 
                ixz="1e-3"
                iyy="5.0409e-3" 
                iyz="-1e-3"
                izz="5.865e-3" />
    </inertial>
  </link>
  
  
  
  
  
  <joint name="MX-64T_15_to_FR05-S101_3" type="fixed">
        <parent link="MX-64T_15"/>
        <child link="FR05-S101_3"/>
        <origin rpy="0 0 1.57" xyz="0.023999 0.0 0.0"/>
    </joint>
    
    <!-- 0.00525 -0.0001 -0.00165 -->
   <link name="FR05-S101_3">
    <visual>
      <origin xyz="0 0 0" rpy="0 0 0" /> <!-- xyz w.r.t. joint's xyz -->
      <geometry>
        <mesh filename="package://darnet_description/meshes/darnet_stl/kaki_kanan/FR05-S101.stl" scale="0.001 0.001 0.001" />
      </geometry>
      <material name="grey" /> <!-- unfortunately you cant give color to stl files in gazebo -->
    </visual>
    <collision>
      <origin xyz="0 0 0" rpy="0 0 0" /> <!-- in radians -->
      <geometry>
        <mesh filename="package://darnet_description/meshes/darnet_stl/kaki_kanan/FR05-S101.stl" scale="0.001 0.001 0.001" />
      </geometry>
    </collision>
    <inertial>
      <origin xyz="-0.001 0.003 0" rpy="0 0 0" /> 
      <mass value="0.022" /> <!-- in kg -->
      <!--  -->
      <inertia
                ixx="1.0609e-3" 
                ixy="1e-3" 
                ixz="1e-3"
                iyy="5.0409e-3" 
                iyz="1e-3"
                izz="5.865e-3" />
    </inertial>
  </link>
  
  
  
  
  
  <joint name="FR05-S101_3_to_FR05-F101_2" type="fixed">
        <parent link="FR05-S101_3"/>
        <child link="FR05-F101_2"/>
        <origin rpy="1.57 0 0" xyz="0 0 0"/>
    </joint>
    
    <!-- 0.00525 -0.0001 -0.00165 -->
   <link name="FR05-F101_2">
    <visual>
      <origin xyz="0 0 0" rpy="0 0 0" /> <!-- xyz w.r.t. joint's xyz -->
      <geometry>
        <mesh filename="package://darnet_description/meshes/darnet_stl/kaki_kanan/FR05-F101.stl" scale="0.001 0.001 0.001" />
      </geometry>
      <material name="grey" /> <!-- unfortunately you cant give color to stl files in gazebo -->
    </visual>
    <collision>
      <origin xyz="0 0 0" rpy="0 0 0" /> <!-- in radians -->
      <geometry>
        <mesh filename="package://darnet_description/meshes/darnet_stl/kaki_kanan/FR05-F101.stl" scale="0.001 0.001 0.001" />
      </geometry>
    </collision>
    <inertial>
      <origin xyz="0 0 0.001" rpy="0 0 0" /> 
      <mass value="0.008" /> <!-- in kg -->
      <!--  -->
      <inertia
                ixx="1.0609e-3" 
                ixy="-1e-3" 
                ixz="1e-3"
                iyy="5.0409e-3" 
                iyz="1e-3"
                izz="5.865e-3" />
    </inertial>
  </link>
  
  
  
  
  
  <joint name="FR05-F101_2_to_HN05-i101_2" type="fixed">
        <parent link="FR05-F101_2"/>
        <child link="HN05-i101_2"/>
        <origin rpy="1.57 0 0" xyz="0 0.000016 0.0058"/>
    </joint>
    
    <!-- 0.00525 -0.0001 -0.00165 -->
   <link name="HN05-i101_2">
    <visual>
      <origin xyz="0 0 0" rpy="0 0 0" /> <!-- xyz w.r.t. joint's xyz -->
      <geometry>
        <mesh filename="package://darnet_description/meshes/darnet_stl/kaki_kanan/HN05-i101.stl" scale="0.001 0.001 0.001" />
      </geometry>
      <material name="grey" /> <!-- unfortunately you cant give color to stl files in gazebo -->
    </visual>
    <collision>
      <origin xyz="0 0 0" rpy="0 0 0" /> <!-- in radians -->
      <geometry>
        <mesh filename="package://darnet_description/meshes/darnet_stl/kaki_kanan/HN05-i101.stl" scale="0.001 0.001 0.001" />
      </geometry>
    </collision>
    <inertial>
      <origin xyz="0 -0.001 0" rpy="0 0 0" /> 
      <mass value="0.01" /> <!-- in kg -->
      <!--  -->
      <inertia
                ixx="1.0609e-3" 
                ixy="1e-3" 
                ixz="1e-3"
                iyy="5.0409e-3" 
                iyz="-1e-3"
                izz="5.865e-3" />
    </inertial>
  </link>
  
  
  
  
  <joint name="HN05-i101_2_to_MF128ZZ_2" type="fixed">
        <parent link="HN05-i101_2"/>
        <child link="MF128ZZ_2"/>
        <origin rpy="0 0 0" xyz="0 -0.001 0"/>
    </joint>
    
    <!-- 0.00525 -0.0001 -0.00165 -->
   <link name="MF128ZZ_2">
    <visual>
      <origin xyz="0 0 0" rpy="0 0 0" /> <!-- xyz w.r.t. joint's xyz -->
      <geometry>
        <mesh filename="package://darnet_description/meshes/darnet_stl/kaki_kanan/MF128ZZ.stl" scale="0.001 0.001 0.001" />
      </geometry>
      <material name="grey" /> <!-- unfortunately you cant give color to stl files in gazebo -->
    </visual>
    <collision>
      <origin xyz="0 0 0" rpy="0 0 0" /> <!-- in radians -->
      <geometry>
        <mesh filename="package://darnet_description/meshes/darnet_stl/kaki_kanan/MF128ZZ.stl" scale="0.001 0.001 0.001" />
      </geometry>
    </collision>
    <inertial>
      <origin xyz="0 0.002 0" rpy="0 0 0" /> 
      <mass value="0.002" /> <!-- in kg -->
      <!--  -->
      <inertia
                ixx="1.0609e-3" 
                ixy="-1e-3" 
                ixz="1e-3"
                iyy="5.0409e-3" 
                iyz="1e-3"
                izz="5.865e-3" />
    </inertial>
  </link>
  
  
  
  
  <joint name="MF128ZZ_2_to_RX64-CAP_2" type="fixed">
        <parent link="MF128ZZ_2"/>
        <child link="RX64-CAP_2"/>
        <origin rpy="-1.57 0 0" xyz="0 0.00468 -0.000013"/>
    </joint>
    
    <!-- 0.00525 -0.0001 -0.00165 -->
   <link name="RX64-CAP_2">
    <visual>
      <origin xyz="0 0 0" rpy="0 0 0" /> <!-- xyz w.r.t. joint's xyz -->
      <geometry>
        <mesh filename="package://darnet_description/meshes/darnet_stl/kaki_kanan/RX64-CAP.stl" scale="0.001 0.001 0.001" />
      </geometry>
      <material name="grey" /> <!-- unfortunately you cant give color to stl files in gazebo -->
    </visual>
    <collision>
      <origin xyz="0 0 0" rpy="0 0 0" /> <!-- in radians -->
      <geometry>
        <mesh filename="package://darnet_description/meshes/darnet_stl/kaki_kanan/RX64-CAP.stl" scale="0.001 0.001 0.001" />
      </geometry>
    </collision>
    <inertial>
      <origin xyz="0 0 0" rpy="0 0 0" /> 
      <mass value="0.001" /> <!-- in kg -->
      <!--  -->
      <inertia
                ixx="1.0609e-3" 
                ixy="-1e-3" 
                ixz="-1e-3"
                iyy="5.0409e-3" 
                iyz="-1e-3"
                izz="5.865e-3" />
    </inertial>
  </link>
  
  
  
  
  
  
  
  
  
  
  
  <joint name="MX-64T_15_to_MX-64T_17" type="fixed">
        <parent link="MX-64T_15"/>
        <child link="MX-64T_17"/>
        <origin rpy="0 1.57 0" xyz="-0.051698 0.0 0.0"/>
    </joint>
    
   <link name="MX-64T_17">
    <visual>
      <origin xyz="0 0 0" rpy="0 0 0" /> <!-- xyz w.r.t. joint's xyz -->
      <geometry>
        <mesh filename="package://darnet_description/meshes/darnet_stl/kaki_kanan/MX-64T.stl" scale="0.001 0.001 0.001" />
      </geometry>
      <material name="grey" /> <!-- unfortunately you cant give color to stl files in gazebo -->
    </visual>
    <collision>
      <origin xyz="0 0 0" rpy="0 0 0" /> <!-- in radians -->
      <geometry>
        <mesh filename="package://darnet_description/meshes/darnet_stl/kaki_kanan/MX-64T.stl" scale="0.001 0.001 0.001" />
      </geometry>
    </collision>
    <inertial>
      <origin xyz="0 -0.015 0" rpy="0 0 0" /> 
      <mass value="0.135" /> <!-- in kg -->
      <!--  -->
      <inertia
                ixx="1.0609e-3" 
                ixy="1e-3" 
                ixz="1e-3"
                iyy="5.0409e-3" 
                iyz="1e-3"
                izz="5.865e-3" />
    </inertial>
  </link>
  
  
  
  
  
  <joint name="MX-64T_17_to_PahaAtas3D_2" type="revolute">
        <parent link="MX-64T_17"/>
        <child link="PahaAtas3D_2"/>
        <origin rpy="0 0 0" xyz="0 0 0"/>
        <axis xyz="0 0 1"/>
        <limit effort="1.4" lower="-2.15" upper="2.15" velocity="6.96"/>
        <dynamics damping="0.0" friction="0.0"/>
    </joint>
    <!--0.01405 0.0384 0.083222  3.14 -1.57 0-->
   <link name="PahaAtas3D_2">
    <visual>
      <origin xyz="0.01405 0.0384 0.083222" rpy="3.14 -1.57 0" />
      <geometry>
        <mesh filename="package://darnet_description/meshes/darnet_stl/kaki_kanan/PahaAtas3D.stl" scale="0.001 0.001 0.001" />
      </geometry>
      <material name="black" /> <!-- unfortunately you cant give color to stl files in gazebo -->
    </visual>
    <collision>
      <origin xyz="0.01405 0.0384 0.083222" rpy="3.14 -1.57 0" /> <!-- in radians -->
      <geometry>
        <mesh filename="package://darnet_description/meshes/darnet_stl/kaki_kanan/PahaAtas3D.stl" scale="0.001 0.001 0.001" />
      </geometry>
    </collision>
    <inertial> <!-- in inventor: -0.028 0.010 -0.014 -->
      <origin xyz="-0.01395 0.0484 0.069222" rpy="0 0 0" />
      <mass value="0.068" /> <!-- in kg -->
      <!--  -->
      <inertia
                ixx="1.0609e-3" 
                ixy="1e-3" 
                ixz="-1e-3"
                iyy="5.0409e-3" 
                iyz="1e-3"
                izz="5.865e-3" />
    </inertial>
  </link>
  
  
</robot>
